ERROR:app:Exception on /auth/register [POST]
Traceback (most recent call last):
  File "/home/runner/InvestCalculator/.pythonlibs/lib/python3.11/site-packages/sqlalchemy/orm/clsregistry.py", line 516, in _resolve_name
    rval = d[token]
           ~^^^^^^^
  File "/home/runner/InvestCalculator/.pythonlibs/lib/python3.11/site-packages/sqlalchemy/util/_collections.py", line 345, in __missing__
    self[key] = val = self.creator(key)
                      ^^^^^^^^^^^^^^^^^
  File "/home/runner/InvestCalculator/.pythonlibs/lib/python3.11/site-packages/sqlalchemy/orm/clsregistry.py", line 484, in _access_cls
    return self.fallback[key]
           ~~~~~~~~~~~~~^^^^^
KeyError: 'Trade'

The above exception was the direct cause of the following exception:

Traceback (most recent call last):
  File "/home/runner/InvestCalculator/.pythonlibs/lib/python3.11/site-packages/flask/app.py", line 1473, in wsgi_app
    response = self.full_dispatch_request()
               ^^^^^^^^^^^^^^^^^^^^^^^^^^^^
  File "/home/runner/InvestCalculator/.pythonlibs/lib/python3.11/site-packages/flask/app.py", line 882, in full_dispatch_request
    rv = self.handle_user_exception(e)
         ^^^^^^^^^^^^^^^^^^^^^^^^^^^^^
  File "/home/runner/InvestCalculator/.pythonlibs/lib/python3.11/site-packages/flask/app.py", line 880, in full_dispatch_request
    rv = self.dispatch_request()
         ^^^^^^^^^^^^^^^^^^^^^^^
  File "/home/runner/InvestCalculator/.pythonlibs/lib/python3.11/site-packages/flask/app.py", line 865, in dispatch_request
    return self.ensure_sync(self.view_functions[rule.endpoint])(**view_args)  # type: ignore[no-any-return]
           ^^^^^^^^^^^^^^^^^^^^^^^^^^^^^^^^^^^^^^^^^^^^^^^^^^^^^^^^^^^^^^^^^
  File "/home/runner/InvestCalculator/routes/auth.py", line 33, in register
    if User.query.filter_by(email=email).first():
       ^^^^^^^^^^
  File "/home/runner/InvestCalculator/.pythonlibs/lib/python3.11/site-packages/flask_sqlalchemy/model.py", line 22, in __get__
    return cls.query_class(
           ^^^^^^^^^^^^^^^^
  File "/home/runner/InvestCalculator/.pythonlibs/lib/python3.11/site-packages/sqlalchemy/orm/query.py", line 275, in __init__
    self._set_entities(entities)
  File "/home/runner/InvestCalculator/.pythonlibs/lib/python3.11/site-packages/sqlalchemy/orm/query.py", line 287, in _set_entities
    self._raw_columns = [
                        ^
  File "/home/runner/InvestCalculator/.pythonlibs/lib/python3.11/site-packages/sqlalchemy/orm/query.py", line 288, in <listcomp>
    coercions.expect(
  File "/home/runner/InvestCalculator/.pythonlibs/lib/python3.11/site-packages/sqlalchemy/sql/coercions.py", line 388, in expect
    insp._post_inspect
  File "/home/runner/InvestCalculator/.pythonlibs/lib/python3.11/site-packages/sqlalchemy/util/langhelpers.py", line 1253, in __get__
    obj.__dict__[self.__name__] = result = self.fget(obj)
                                           ^^^^^^^^^^^^^^
  File "/home/runner/InvestCalculator/.pythonlibs/lib/python3.11/site-packages/sqlalchemy/orm/mapper.py", line 2722, in _post_inspect
    self._check_configure()
  File "/home/runner/InvestCalculator/.pythonlibs/lib/python3.11/site-packages/sqlalchemy/orm/mapper.py", line 2399, in _check_configure
    _configure_registries({self.registry}, cascade=True)
  File "/home/runner/InvestCalculator/.pythonlibs/lib/python3.11/site-packages/sqlalchemy/orm/mapper.py", line 4215, in _configure_registries
    _do_configure_registries(registries, cascade)
  File "/home/runner/InvestCalculator/.pythonlibs/lib/python3.11/site-packages/sqlalchemy/orm/mapper.py", line 4256, in _do_configure_registries
    mapper._post_configure_properties()
  File "/home/runner/InvestCalculator/.pythonlibs/lib/python3.11/site-packages/sqlalchemy/orm/mapper.py", line 2416, in _post_configure_properties
    prop.init()
  File "/home/runner/InvestCalculator/.pythonlibs/lib/python3.11/site-packages/sqlalchemy/orm/interfaces.py", line 589, in init
    self.do_init()
  File "/home/runner/InvestCalculator/.pythonlibs/lib/python3.11/site-packages/sqlalchemy/orm/relationships.py", line 1642, in do_init
    self._setup_entity()
  File "/home/runner/InvestCalculator/.pythonlibs/lib/python3.11/site-packages/sqlalchemy/orm/relationships.py", line 1854, in _setup_entity
    self._clsregistry_resolve_name(argument)(),
    ^^^^^^^^^^^^^^^^^^^^^^^^^^^^^^^^^^^^^^^^^^
  File "/home/runner/InvestCalculator/.pythonlibs/lib/python3.11/site-packages/sqlalchemy/orm/clsregistry.py", line 520, in _resolve_name
    self._raise_for_name(name, err)
  File "/home/runner/InvestCalculator/.pythonlibs/lib/python3.11/site-packages/sqlalchemy/orm/clsregistry.py", line 501, in _raise_for_name
    raise exc.InvalidRequestError(
sqlalchemy.exc.InvalidRequestError: When initializing mapper Mapper[User(user)], expression 'Trade' failed to locate a name ('Trade'). If this is a class name, consider adding this relationship() to the <class 'models.user.User'> class after both dependent classes have been defined.
INFO:werkzeug:172.31.196.247 - - [28/Oct/2024 18:55:59] "POST /auth/register HTTP/1.1" 500 -