ERROR:app:Exception on /auth/login [GET]
Traceback (most recent call last):
  File "/home/runner/InvestCalculator/.pythonlibs/lib/python3.11/site-packages/flask/app.py", line 1473, in wsgi_app
    response = self.full_dispatch_request()
               ^^^^^^^^^^^^^^^^^^^^^^^^^^^^
  File "/home/runner/InvestCalculator/.pythonlibs/lib/python3.11/site-packages/flask/app.py", line 882, in full_dispatch_request
    rv = self.handle_user_exception(e)
         ^^^^^^^^^^^^^^^^^^^^^^^^^^^^^
  File "/home/runner/InvestCalculator/.pythonlibs/lib/python3.11/site-packages/flask/app.py", line 880, in full_dispatch_request
    rv = self.dispatch_request()
         ^^^^^^^^^^^^^^^^^^^^^^^
  File "/home/runner/InvestCalculator/.pythonlibs/lib/python3.11/site-packages/flask/app.py", line 865, in dispatch_request
    return self.ensure_sync(self.view_functions[rule.endpoint])(**view_args)  # type: ignore[no-any-return]
           ^^^^^^^^^^^^^^^^^^^^^^^^^^^^^^^^^^^^^^^^^^^^^^^^^^^^^^^^^^^^^^^^^
  File "/home/runner/InvestCalculator/routes/auth.py", line 23, in login
    return render_template('auth/login.html')
           ^^^^^^^^^^^^^^^^^^^^^^^^^^^^^^^^^^
  File "/home/runner/InvestCalculator/.pythonlibs/lib/python3.11/site-packages/flask/templating.py", line 150, in render_template
    return _render(app, template, context)
           ^^^^^^^^^^^^^^^^^^^^^^^^^^^^^^^
  File "/home/runner/InvestCalculator/.pythonlibs/lib/python3.11/site-packages/flask/templating.py", line 127, in _render
    app.update_template_context(context)
  File "/home/runner/InvestCalculator/.pythonlibs/lib/python3.11/site-packages/flask/app.py", line 493, in update_template_context
    context.update(self.ensure_sync(func)())
                   ^^^^^^^^^^^^^^^^^^^^^^^^
  File "/home/runner/InvestCalculator/.pythonlibs/lib/python3.11/site-packages/flask_login/utils.py", line 405, in _user_context_processor
    return dict(current_user=_get_user())
                             ^^^^^^^^^^^
  File "/home/runner/InvestCalculator/.pythonlibs/lib/python3.11/site-packages/flask_login/utils.py", line 370, in _get_user
    current_app.login_manager._load_user()
  File "/home/runner/InvestCalculator/.pythonlibs/lib/python3.11/site-packages/flask_login/login_manager.py", line 364, in _load_user
    user = self._user_callback(user_id)
           ^^^^^^^^^^^^^^^^^^^^^^^^^^^^
  File "/home/runner/InvestCalculator/app.py", line 40, in load_user
    return User.query.get(int(id))
           ^^^^^^^^^^
  File "/home/runner/InvestCalculator/.pythonlibs/lib/python3.11/site-packages/flask_sqlalchemy/model.py", line 22, in __get__
    return cls.query_class(
           ^^^^^^^^^^^^^^^^
  File "/home/runner/InvestCalculator/.pythonlibs/lib/python3.11/site-packages/sqlalchemy/orm/query.py", line 275, in __init__
    self._set_entities(entities)
  File "/home/runner/InvestCalculator/.pythonlibs/lib/python3.11/site-packages/sqlalchemy/orm/query.py", line 287, in _set_entities
    self._raw_columns = [
                        ^
  File "/home/runner/InvestCalculator/.pythonlibs/lib/python3.11/site-packages/sqlalchemy/orm/query.py", line 288, in <listcomp>
    coercions.expect(
  File "/home/runner/InvestCalculator/.pythonlibs/lib/python3.11/site-packages/sqlalchemy/sql/coercions.py", line 388, in expect
    insp._post_inspect
  File "/home/runner/InvestCalculator/.pythonlibs/lib/python3.11/site-packages/sqlalchemy/util/langhelpers.py", line 1253, in __get__
    obj.__dict__[self.__name__] = result = self.fget(obj)
                                           ^^^^^^^^^^^^^^
  File "/home/runner/InvestCalculator/.pythonlibs/lib/python3.11/site-packages/sqlalchemy/orm/mapper.py", line 2722, in _post_inspect
    self._check_configure()
  File "/home/runner/InvestCalculator/.pythonlibs/lib/python3.11/site-packages/sqlalchemy/orm/mapper.py", line 2399, in _check_configure
    _configure_registries({self.registry}, cascade=True)
  File "/home/runner/InvestCalculator/.pythonlibs/lib/python3.11/site-packages/sqlalchemy/orm/mapper.py", line 4215, in _configure_registries
    _do_configure_registries(registries, cascade)
  File "/home/runner/InvestCalculator/.pythonlibs/lib/python3.11/site-packages/sqlalchemy/orm/mapper.py", line 4252, in _do_configure_registries
    raise e
sqlalchemy.exc.InvalidRequestError: One or more mappers failed to initialize - can't proceed with initialization of other mappers. Triggering mapper: 'Mapper[User(user)]'. Original exception was: Error creating backref 'user' on relationship 'User.sales': property of that name exists on mapper 'Mapper[Sale(sale)]'
INFO:werkzeug:172.31.196.159 - - [28/Oct/2024 22:43:05] "GET /auth/login HTTP/1.1" 500 -
